<?xml version="1.0" ?>
<robot name="Model_Robot">
  <joint name="Model_Robot__link_JOINT_2" type="revolute">
    <parent link="Model_Robot__link"/>
    <child link="Model_Robot__link_0_clone_0"/>
    <origin xyz="-0.15 -0.2  -0.15" rpy="0 0 0"/>
    <axis xyz="1 0 0"/>
    <limit lower="-1.79769e+308" upper="1.79769e+308" effort="-1.0" velocity="-1.0"/>
  </joint>
  <joint name="Model_Robot__link_JOINT_3" type="revolute">
    <parent link="Model_Robot__link"/>
    <child link="Model_Robot__link_0"/>
    <origin xyz="-0.15  0.2  -0.15" rpy="0 0 0"/>
    <axis xyz="1 0 0"/>
    <limit lower="-1.79769e+308" upper="1.79769e+308" effort="-1.0" velocity="-1.0"/>
  </joint>
  <joint name="Model_Robot__link_JOINT_5" type="revolute">
    <parent link="Model_Robot__link"/>
    <child link="Model_Robot__link_0_clone"/>
    <origin xyz="0.15  0.2  -0.15" rpy="0 0 0"/>
    <axis xyz="1 0 0"/>
    <limit lower="-1.79769e+308" upper="1.79769e+308" effort="-1.0" velocity="-1.0"/>
  </joint>
  <joint name="Model_Robot__link_JOINT_6" type="revolute">
    <parent link="Model_Robot__link"/>
    <child link="Model_Robot__link_0_clone_0_clone"/>
    <origin xyz="0.15 -0.2  -0.15" rpy="0 0 0"/>
    <axis xyz="1 0 0"/>
    <limit lower="-1.79769e+308" upper="1.79769e+308" effort="-1.0" velocity="-1.0"/>
  </joint>
  <link name="Model_Robot__link">
    <inertial>
      <mass value="1"/>
      <origin xyz="0 0 0" rpy="0 0 0"/>
      <inertia ixx="0.166667" ixy="0" ixz="0" iyy="0.166667" iyz="0" izz="0.166667"/>
    </inertial>
    <collision name="Model_Robot__collision">
      <origin xyz="0 0 0" rpy="0 0 0"/>
      <geometry>
        <box size="0.3 0.3 0.3"/>
      </geometry>
    </collision>
    <visual name="Model_Robot__visual">
      <origin xyz="0 0 0" rpy="0 0 0"/>
      <geometry>
        <box size="0.3 0.3 0.3"/>
      </geometry>
    </visual>
  </link>
  <link name="Model_Robot__link_0">
    <inertial>
      <mass value="1"/>
      <origin xyz="0 0 0" rpy="0 0 0"/>
      <inertia ixx="0.145833" ixy="0" ixz="0" iyy="0.145833" iyz="0" izz="0.125"/>
    </inertial>
    <collision name="Model_Robot__collision">
      <origin xyz="0 0 0" rpy="1.57057 0      0"/>
      <geometry>
        <cylinder radius="0.08" length="0.1"/>
      </geometry>
    </collision>
    <visual name="Model_Robot__visual">
      <origin xyz="0 0 0" rpy="1.57057 0      0"/>
      <geometry>
        <cylinder radius="0.08" length="0.1"/>
      </geometry>
    </visual>
  </link>
  <link name="Model_Robot__link_0_clone">
    <inertial>
      <mass value="1"/>
      <origin xyz="0 0 0" rpy="0 0 0"/>
      <inertia ixx="0.145833" ixy="0" ixz="0" iyy="0.145833" iyz="0" izz="0.125"/>
    </inertial>
    <collision name="Model_Robot__collision">
      <origin xyz="0 0 0" rpy="1.57057 0      0"/>
      <geometry>
        <cylinder radius="0.08" length="0.1"/>
      </geometry>
    </collision>
    <visual name="Model_Robot__visual">
      <origin xyz="0 0 0" rpy="1.57057 0      0"/>
      <geometry>
        <cylinder radius="0.08" length="0.1"/>
      </geometry>
    </visual>
  </link>
  <link name="Model_Robot__link_0_clone_0">
    <inertial>
      <mass value="1"/>
      <origin xyz="0 0 0" rpy="0 0 0"/>
      <inertia ixx="0.145833" ixy="0" ixz="0" iyy="0.145833" iyz="0" izz="0.125"/>
    </inertial>
    <collision name="Model_Robot__collision">
      <origin xyz="0 0 0" rpy="1.57057 0      0"/>
      <geometry>
        <cylinder radius="0.08" length="0.1"/>
      </geometry>
    </collision>
    <visual name="Model_Robot__visual">
      <origin xyz="0 0 0" rpy="1.57057 0      0"/>
      <geometry>
        <cylinder radius="0.08" length="0.1"/>
      </geometry>
    </visual>
  </link>
  <link name="Model_Robot__link_0_clone_0_clone">
    <inertial>
      <mass value="1"/>
      <origin xyz="0 0 0" rpy="0 0 0"/>
      <inertia ixx="0.145833" ixy="0" ixz="0" iyy="0.145833" iyz="0" izz="0.125"/>
    </inertial>
    <collision name="Model_Robot__collision">
      <origin xyz="0 0 0" rpy="1.57057 0      0"/>
      <geometry>
        <cylinder radius="0.08" length="0.1"/>
      </geometry>
    </collision>
    <visual name="Model_Robot__visual">
      <origin xyz="0 0 0" rpy="1.57057 0      0"/>
      <geometry>
        <cylinder radius="0.08" length="0.1"/>
      </geometry>
    </visual>
  </link>
</robot>
